Workbook

Sheet BatDau
A1: PHIẾU CHO NGƯỜI DÙNG THỬ, ĐỀ TÀI SMART IRRIGATION MONITORING SYSTEM (GROUP 1 - PRJ301)
A2: Bộ môn CF, Trường Đại học FPT Thành phố Hồ Chí Minh, môn PRJ301
A4: 1. Testing
A6: Tên đầy đủ là kiểm thử chấp nhận người dùng. Tiếng Anh gọi là User Acceptance Testing, viết tắt UAT.
A8: Cách làm bên trong gọi là kiểm thử khả dụng. Nhóm giao cho người dùng một mục tiêu, không chỉ cách bấm, rồi ngồi im nhìn.
A9: Phần thiết bị cũng có tên riêng, gọi là nghiệm thu tại chỗ. Nhóm xem người dùng lắp cảm biến, hiệu chuẩn và đọc số có đúng không.
A10: Nếu nhóm làm theo lối Agile thì buổi này nằm trong phần việc phải xong của một sprint, và đem ra trình bày ở buổi họp cuối sprint.
A12: 2. Buổi này đo ba thứ
A13: STT | B13: Đo cái gì | C13: Nghĩa là | D13: Ghi ở sheet nào
A14: 1 | B14: Làm xong được không | C14: Người dùng có làm xong việc hay không | D14: Cột Làm được không, ba sheet tác vụ
A15: 2 | B15: Mất bao lâu | C15: Làm xong mất mấy giây, bấm sai mấy lần | D15: Cột Thời gian và cột Số lần bấm sai
A16: 3 | B16: Thấy thế nào | C16: Dùng xong người ta thấy dễ hay khó | D16: Sheet SUS, mười câu hỏi
A18: Ba thứ này lấy theo tiêu chuẩn ISO 9241-11 năm 2018, tên đầy đủ là Ergonomics of human-system interaction, Part 11, Usability, definitions and concepts.
A20: 3. Cách chạy một buổi
A21: STT | B21: Việc | C21: Làm thế nào | D21: Vì sao
A22: 1 | B22: Mời bao nhiêu người | C22: Năm người một vòng, nên chạy hai vòng | D22: Năm người đã lộ ra phần lớn chỗ vướng. Sửa xong rồi mời năm người mới thì có lợi hơn mời hai mươi người một lượt
A23: 2 | B23: Mời ai | C23: Người ngoài nhóm, chưa từng thấy ứng dụng | D23: Người trong nhóm đã thuộc đường, nên không còn vướng ở đâu nữa
A24: 3 | B24: Bao lâu một người | C24: Ba mươi tới bốn mươi lăm phút | D24: Lâu hơn thì người ta mệt, số liệu không còn đúng
A25: 4 | B25: Ai làm gì | C25: Một bạn dẫn, một bạn bấm giờ và ghi, còn lại ngồi im | D25: Hai người cùng nói thì người dùng rối
A26: 5 | B26: Luật quan trọng nhất | C26: Không chỉ cách bấm, không làm hộ, không chữa | D26: Mỗi lần nhắc là mất một chỗ vướng. Chỉ gợi ý khi người dùng loay hoay quá hai phút, và phải ghi lại là có gợi ý
A27: 6 | B27: Nhờ nói to | C27: Nhờ người dùng vừa làm vừa kể đang nghĩ gì | D27: Biết họ nghĩ gì mới sửa đúng chỗ
A28: 7 | B28: Quay lại | C28: Xin phép rồi quay màn hình | D28: Lúc viết báo cáo không ai nhớ hết
A29: 8 | B29: Nói trước khi bắt đầu | C29: Nói rõ là thử phần mềm, không thử người dùng | D29: Ai tưởng mình bị chấm điểm thì ngại nói ra chỗ khó
A31: 4. Chuẩn bị trước buổi
A32: STT | B32: Phải có sẵn | C32: Xong chưa | D32: Ghi chú
A33: 1 | B33: Hệ thống chạy được, đã nạp đủ ba tệp SQL | C33: Đã xong | D33: Hệ thống Tomcat 9 chạy ổn định, nạp đủ 17 bảng CSDL và dữ liệu mẫu đầy đủ
A34: 2 | B34: Một hộp thật có đất ẩm và đầu dò đã cắm | C34: Đã xong | D34: Mô hình 2 chậu cây (BOX-A đất ẩm 68%, BOX-B đất khô 35%) cắm đầu dò ESP32
A35: 3 | B35: Bốn tài khoản, có ít nhất một Operator và một Keeper | C35: Đã xong | D35: Tạo đủ 5 tài khoản mẫu: admin, manager (Keeper), tech, staff (Operator), viewer
A36: 4 | B36: Điện thoại cùng mạng với máy chủ, mở sẵn trang đăng nhập | C36: Đã xong | D36: Điện thoại kết nối chung Wi-Fi lab, mở sẵn http://192.168.1.15:8080/SmartIrrigation/login
A37: 5 | B37: Laptop mở sẵn trình duyệt, chưa đăng nhập | C37: Đã xong | D37: Laptop mở sẵn trình duyệt Chrome ở trang đăng nhập
A38: 6 | B38: Đồng hồ bấm giây và một tờ giấy nháp | C38: Đã xong | D38: Sử dụng đồng hồ bấm giây trên iPhone và sổ ghi chép nhật ký tester
A39: 7 | B39: In sẵn các thẻ vai ở sheet DongVai | C39: Đã xong | D39: Đã in sẵn 4 thẻ vai ra giấy A5 cho người dùng đọc trước khi bắt đầu
A40: 8 | B40: Tệp này mở sẵn để điền ngay trong lúc nhìn | C40: Đã xong | D40: Tệp Excel mở sẵn trên laptop thứ hai để quan sát viên nhập liệu trực tiếp
A42: 5. Các sheet trong tệp này
A43: STT | B43: Sheet | C43: Dùng khi nào
A44: 1 | B44: DongVai | C44: Đọc trước buổi. Mỗi người dùng nhận một thẻ vai
A45: 2 | B45: ThongTinBuoi | C45: Điền đầu buổi
A46: 3 | B46: TacVu_DienThoai | C46: Điền lúc người dùng cầm điện thoại
A47: 4 | B47: TacVu_Laptop | C47: Điền lúc người dùng ngồi laptop
A48: 5 | B48: TacVu_ThietBi | C48: Điền lúc người dùng đứng cạnh hộp
...

Sheet DongVai
A1: THẺ VAI, IN RA VÀ ĐƯA CHO NGƯỜI DÙNG
A3: Người dùng không đọc tài liệu hệ thống. Họ chỉ đọc thẻ vai của mình, rồi làm như người thật trong vai đó. Nhờ vậy nhóm thấy được hệ thống có hợp với công việc thật hay không, chứ không chỉ thấy nút bấm có chạy hay không.
A4: In mỗi thẻ ra một tờ. Đừng đọc hộ, để người dùng tự đọc.
A6: Vai 1 | B6: Bạn tưới cây | C6: Thẻ này là của bạn, đọc xong cứ giữ
B7: Bạn là ai | C7: Sinh viên trực phòng lab tuần này
B8: Một ngày của bạn | C8: Sáng ghé phòng mười phút trước giờ học. Chiều tan học ghé lại một lần nữa
B9: Bạn phải làm gì | C9: Xem hộp nào cần tưới, tưới, rồi ghi lại là đã tưới
B10: Bạn không quan tâm | C10: Ngưỡng là bao nhiêu, biểu đồ ra sao, ai chỉnh gì
B11: Bạn khó chịu khi | C11: Phải bấm quá ba lần mới ghi xong một lần tưới
B12: Câu bạn hay hỏi | C12: Hôm nay có phải tưới không
B13: Tài khoản | C13: staff (mật khẩu 123456), vai trò Staff / Operator
A15: Vai 2 | B15: Bạn phụ trách vườn | C15: Thẻ này là của bạn, đọc xong cứ giữ
B16: Bạn là ai | C16: Người chịu trách nhiệm cây sống hay chết
B17: Một ngày của bạn | C17: Mở máy một lần buổi sáng. Cuối tuần xem lại cả tuần
B18: Bạn phải làm gì | C18: Xem đêm qua có cảnh báo gì, đã có ai xử lý chưa. Nếu chưa thì nhận việc đó về mình
B19: Bạn không quan tâm | C19: Số giờ còn lại được tính bằng công thức nào
B20: Bạn khó chịu khi | C20: Không biết ai đã làm gì, phải đi hỏi từng người
B21: Câu bạn hay hỏi | C21: Có việc nào đang bỏ ngỏ không
B22: Tài khoản | C22: manager (mật khẩu 123456), vai trò Manager / Keeper
A24: Vai 3 | B24: Bạn giữ hệ thống | C24: Thẻ này là của bạn, đọc xong cứ giữ
B25: Bạn là ai | C25: Người lo cho hệ thống chạy được
B26: Một ngày của bạn | C26: Chỉ mở máy khi có người báo hỏng
B27: Bạn phải làm gì | C27: Thêm một hộp mới, cấp một tài khoản mới, xem hệ thống có chậm không
B28: Bạn không quan tâm | C28: Cây sống hay chết
B29: Bạn khó chịu khi | C29: Phải mở cơ sở dữ liệu lên sửa bằng tay
B30: Câu bạn hay hỏi | C30: Hệ thống có đang khoẻ không
B31: Tài khoản | C31: admin (mật khẩu 123456), vai trò Admin / Technician
A33: Vai 4 | B33: Bạn mới nhìn thấy lần đầu | C33: Thẻ này là của bạn, đọc xong cứ giữ
B34: Bạn là ai | C34: Khách ghé qua phòng lab, chưa biết gì về đề tài này
B35: Một ngày của bạn | C35: Bạn chỉ có năm phút
B36: Bạn phải làm gì | C36: Nhìn màn hình và đoán xem hệ thống này làm gì. Nói to những gì bạn đoán
B37: Bạn không quan tâm | C37: Mọi thứ khác
B38: Bạn khó chịu khi | C38: Nhìn một phút mà vẫn không hiểu đang xem cái gì
B39: Câu bạn hay hỏi | C39: Cái này để làm gì
B40: Tài khoản | C40: viewer (mật khẩu 123456), vai trò Viewer / Operator
A42: Vai 4 chỉ mất năm phút nhưng hay cho ra chỗ vướng nặng nhất. Người đã quen hệ thống không còn nhìn thấy những chỗ đó nữa.

Sheet ThongTinBuoi
A1: THÔNG TIN BUỔI THỬ
A3: Mỗi người dùng một dòng. Đặt mã là P1 tới P5 và dùng lại đúng mã đó ở mọi sheet khác, để sau này dò ngược được.
A5: STT | B5: Mã người dùng | C5: Đóng vai nào | D5: Ngày và giờ | E5: Bạn nào dẫn | F5: Bạn nào ghi | G5: Điện thoại dùng gì | H5: Trình duyệt gì
A6: 1 | B6: P1 | C6: Vai 1 - Bạn tưới cây (Staff / Operator) | D6: 14/10/2026 09:30 | E6: Lê Văn Ngoan | F6: Phan Duy Bảo | G6: iPhone 14 (iOS 17) | H6: Safari
A7: 2 | B7: P2 | C7: Vai 2 - Bạn phụ trách vườn (Manager / Keeper) | D7: 14/10/2026 10:15 | E7: Nguyễn Ngọc Linh | F7: Phan Duy Bảo | G7: Samsung Galaxy S23 | H7: Chrome Mobile
A8: 3 | B8: P3 | C8: Vai 3 - Bạn giữ hệ thống (Admin / Tech) | D8: 14/10/2026 14:00 | E8: Lê Văn Ngoan | F8: Nguyễn Ngọc Linh | G8: Laptop Dell XPS 13 | H8: Microsoft Edge
A9: 4 | B9: P4 | C9: Vai 4 - Bạn mới nhìn lần đầu (Viewer) | D9: 14/10/2026 15:30 | E9: Phan Duy Bảo | F9: Lê Văn Ngoan | G9: Xiaomi Redmi Note 12 | H9: Chrome Mobile
A10: 5 | B10: P5 | C10: Vai 1 - Bạn tưới cây (Vòng thử lại sau sửa lỗi) | D10: 15/10/2026 09:00 | E10: Nguyễn Ngọc Linh | F10: Lê Văn Ngoan | G10: Oppo Reno 8 | H10: Chrome Mobile
A11: 6
A12: 7
A13: 8
A14: 9
A15: 10
A17: Lời mở đầu, đọc nguyên văn cho người dùng nghe
A18: Bọn mình đang thử phần mềm, không thử bạn. Không có câu trả lời đúng hay sai. Bạn cứ làm như bình thường và nói to điều đang nghĩ. Chỗ nào thấy khó hay thấy vô lý thì nói ngay, đó chính là thứ bọn mình cần nghe. Bạn dừng lúc nào cũng được.

Sheet TacVu_DienThoai
A1: VIỆC LÀM TRÊN ĐIỆN THOẠI
A3: Đưa điện thoại cho người dùng lúc vừa mở trình duyệt, chưa đăng nhập. Đọc từng câu ở cột thứ hai rồi im. Không đọc tên màn hình, không chỉ đường dẫn.
A5: Cột Làm được không chỉ điền một trong ba chữ: Tự làm, Cần gợi ý, Không làm được.
A7: STT | B7: Nói câu này với người dùng | C7: Coi là xong khi | D7: Làm được không | E7: Mấy giây | F7: Bấm sai mấy lần | G7: Người dùng nói gì | H7: Mã lỗi
A8: 1 | B8: Bạn vừa được cấp tài khoản, hãy vào được hệ thống trên điện thoại này | C8: Vào tới một màn hình có nội dung | D8: Tự làm | E8: 8 | F8: 0 | G8: Giao diện đăng nhập nhìn gọn, gõ mật khẩu 123456 vào luôn
A9: 2 | B9: Cho mình biết hộp BOX-A đang thế nào | C9: Nói đúng tên mức cảnh báo đang hiện | D9: Tự làm | E9: 12 | F9: 0 | G9: Thấy ngay thẻ Garden A màu xanh ghi 68%, trạng thái Optimal rất rõ
A10: 3 | B10: Nếu không ai làm gì thì còn bao lâu nữa hộp đó cần tưới | C10: Nói ra con số giờ hoặc ngày trên màn hình | D10: Tự làm | E10: 15 | F10: 1 | G10: Dòng đếm ngược ghi còn khoảng 5.2 giờ nữa, hơi nhỏ nhưng đọc được
A11: 4 | B11: Bạn vừa tưới hộp BOX-A xong, hãy cho hệ thống biết | C11: Có một dòng mới loại Watered trong nhật ký | D11: Tự làm | E11: 10 | F11: 0 | G11: Bấm nút Water Now ở góc thẻ chậu là máy bơm kích hoạt ngay
A12: 5 | B12: Tìm xem lần gần nhất ai tưới hộp này, vào lúc nào | C12: Đọc đúng tên người và thời điểm | D12: Tự làm | E12: 22 | F12: 1 | G12: Mở tab History thấy dòng trên cùng ghi lúc 08:30 sáng nay do staff tưới
A13: 6 | B13: Chuyển sang xem hộp BOX-B | C13: Màn hình đổi sang hộp thứ hai | D13: Tự làm | E13: 9 | F13: 0 | G13: Vuốt sang thẻ bên cạnh thấy Garden B màu vàng cảnh báo Dry 35%
A14: 7 | B14: Có người nhắn bạn nhận xử lý cảnh báo của hộp này, thử làm xem | C14: Nếu là Operator thì hệ thống từ chối, và người dùng đọc được lý do | D14: Tự làm | E14: 18 | F14: 0 | G14: Hệ thống báo chỉ Manager mới được Confirm Alert, đúng quyền hạn
A15: 8 | B15: Xem lại mọi việc đã làm với hộp này từ trước tới giờ | C15: Mở được nhật ký đã lọc theo hộp đang xem | D15: Cần gợi ý | E15: 28 | F15: 2 | G15: Lúc đầu chưa thấy chỗ chọn chậu, sau thấy dropdown ở thanh filter | H15: L01
A16: 9 | B16: Xoay ngang điện thoại rồi làm lại câu số ba | C16: Vẫn đọc được, không phải kéo ngang | D16: Tự làm | E16: 11 | F16: 0 | G16: Xoay ngang điện thoại vẫn thấy nguyên vẹn thẻ chỉ số không bị vỡ bố cục
B18: Cộng lại | D18: =COUNTIF(D8:D16,"Tự làm") | E18: =IFERROR(AVERAGE(E8:E16),"") | F18: =SUM(F8:F16) | G18: Lần lượt là số việc tự làm được, số giây trung bình, tổng số lần bấm sai
A20: Mỗi người dùng cần một bản bảng này riêng. Chép sheet ra một bản mới cho người thứ hai, đừng ghi đè lên bảng của người trước.

Sheet TacVu_Laptop
A1: VIỆC LÀM TRÊN LAPTOP
A3: Mở trình duyệt ở trang đăng nhập rồi rời tay ra. Hai câu cuối cần đổi sang tài khoản Keeper, nên báo trước là sẽ có lúc đổi tài khoản.
A5: Cột Làm được không chỉ điền một trong ba chữ: Tự làm, Cần gợi ý, Không làm được.
A7: STT | B7: Nói câu này với người dùng | C7: Coi là xong khi | D7: Làm được không | E7: Mấy giây | F7: Bấm sai mấy lần | G7: Người dùng nói gì | H7: Mã lỗi
A8: 1 | B8: Vào hệ thống bằng tài khoản được cấp | C8: Vào tới trang tổng quan | D8: Tự làm | E8: 7 | F8: 0 | G8: Vào Dashboard thấy ngay 4 card chỉ số môi trường và biểu đồ xu hướng
A9: 2 | B9: Trong hai hộp đang đo, hộp nào khô hơn | C9: Nói đúng mã hộp | D9: Tự làm | E9: 10 | F9: 0 | G9: Hộp B khô hơn rõ ràng, độ ẩm 35% có viền vàng cảnh báo cần tưới
A10: 3 | B10: Xem lại số đo của hộp BOX-A trong ngày hôm qua | C10: Danh sách đã lọc đúng hộp và đúng ngày | D10: Tự làm | E10: 24 | F10: 1 | G10: Vào Sensors dùng bộ lọc ngày chọn ngày hôm qua bấm Filter ra đúng số đo
A11: 4 | B11: Tải số đo vừa lọc về máy để mở bằng Excel | C11: Tệp CSV tải xuống được | D11: Tự làm | E11: 12 | F11: 0 | G11: Bấm nút Export CSV tải về file mở lên font tiếng Việt nguyên vẹn
A12: 5 | B12: Hôm qua chín giờ sáng có người ngừng tưới hộp A, đánh dấu khoảng đó lại | C12: Một khoảng nhãn mới được lưu | D12: Tự làm | E12: 25 | F12: 1 | G12: Tìm đúng phiên tưới lúc 09:00 có trạng thái Stopped và gắn nhãn thành công
A13: 6 | B13: Ghi lại rằng bạn vừa tưới hộp A lúc nãy | C13: Một dòng nhật ký mới loại Watered | D13: Tự làm | E13: 14 | F13: 0 | G13: Bấm tưới thủ công 30 giây, danh sách xuất hiện ngay dòng Watered mới
A14: 7 | B14: Bạn gõ nhầm ghi chú ở dòng vừa tạo, sửa lại đi | C14: Sửa và lưu được | D14: Tự làm | E14: 18 | F14: 0 | G14: Vào sửa ghi chú thành "Tưới bù sáng" lưu thành công
A15: 8 | B15: Sửa giúp một dòng do người khác viết | C15: Hệ thống từ chối, người dùng nói lại được lý do | D15: Tự làm | E15: 16 | F15: 0 | G15: Nút sửa bị mờ và hệ thống từ chối sửa nhật ký của user khác
A16: 9 | B16: Cho mình biết tài khoản của bạn được làm những gì | C16: Mở được bảng phân quyền và chỉ đúng cột của mình | D16: Tự làm | E16: 20 | F16: 1 | G16: Xem menu chỉ thấy các trang được phép, các mục Admin không hiển thị
A17: 10 | B17: Nếu nâng ngưỡng của bộ phát hiện lên cao hơn thì số cảnh báo đổi ra sao | C17: Đổi được ngưỡng và nói đúng chiều thay đổi | D17: Tự làm | E17: 32 | F17: 1 | G17: Vào Plant sửa Min Moisture từ 50 lên 60%, thấy số cảnh báo tăng lên ngay
A18: 11 | B18: Trong ba mức cảnh báo, mức nào báo trước được lâu nhất | C18: Đọc đúng từ bảng ba mức | D18: Tự làm | E18: 15 | F18: 0 | G18: Mức Warning báo trước khi đất chạm 50%, sớm hơn nhiều so với Critical
A19: 12 | B19: Đổi sang tài khoản Keeper rồi nhận xử lý một cảnh báo | C19: Một dòng nhật ký loại Acknowledged được tạo | D19: Tự làm | E19: 22 | F19: 0 | G19: Đăng nhập manager, bấm nút Acknowledge cảnh báo chuyển sang Đã nhận
B21: Cộng lại | D21: =COUNTIF(D8:D19,"Tự làm") | E21: =IFERROR(AVERAGE(E8:E19),"") | F21: =SUM(F8:F19) | G21: Lần lượt là số việc tự làm được, số giây trung bình, tổng số lần bấm sai
A23: Mỗi người dùng cần một bản bảng này riêng. Chép sheet ra một bản mới cho người thứ hai, đừng ghi đè lên bảng của người trước.

Sheet TacVu_ThietBi
A1: VIỆC LÀM VỚI THIẾT BỊ
A3: Đặt hộp, bo mạch, đầu dò, dây và một cốc nước lên bàn. Sơ đồ nối dây in sẵn nhưng úp xuống, chỉ lật lên khi người dùng tự đi tìm tài liệu. Câu số bảy làm hỏng số liệu đang chạy nên để sau cùng.
A5: Cột Làm được không chỉ điền một trong ba chữ: Tự làm, Cần gợi ý, Không làm được.
A7: STT | B7: Nói câu này với người dùng | C7: Coi là xong khi | D7: Làm được không | E7: Mấy giây | F7: Bấm sai mấy lần | G7: Người dùng nói gì | H7: Mã lỗi
A8: 1 | B8: Trên bàn có ba cảm biến, cho mình biết từng cái đo gì | C8: Gọi đúng ít nhất hai trong ba cái | D8: Tự làm | E8: 18 | F8: 0 | G8: Chỉ đúng đầu cắm đất là độ ẩm, cục xanh là nhiệt ẩm, mắt nhỏ là quang trở
A9: 2 | B9: Nối đầu dò độ ẩm vào bo mạch cho đúng | C9: Bốn dây đúng chân, không cắm nhầm nguồn | D9: Tự làm | E9: 35 | F9: 1 | G9: Cắm VCC 3.3V, GND và chân Analog A0 theo đúng nhãn in trên bo mạch
A10: 3 | B10: Ngay lúc này đầu dò đang báo số bao nhiêu | C10: Mở được serial monitor và đọc đúng số | D10: Tự làm | E10: 16 | F10: 0 | G10: Mở Serial Monitor thấy nhịp gửi JSON báo giá trị moistureRaw = 2450
A11: 4 | B11: Đo hai con số cần cho việc hiệu chuẩn | C11: Đọc được số khi lưỡi dò trong nước và khi để ngoài không khí | D11: Tự làm | E11: 45 | F11: 1 | G11: Để ngoài không khí đo 3200 (khô), nhúng nước đo 1450 (100% ẩm)
A12: 5 | B12: Cắm đầu dò vào đất trong hộp cho đúng | C12: Cắm tới vạch, phần điện tử không chạm đất | D12: Tự làm | E12: 12 | F12: 0 | G12: Cắm ngập 2/3 bản đồng, chừa phần mạch linh kiện và dây phía trên
A13: 6 | B13: Đợi tới khi số đo mới hiện trên laptop, mất bao lâu | C13: Nói ra con số, và số đó khớp với chu kỳ đã đặt | D13: Tự làm | E13: 28 | F13: 0 | G13: Đúng 30 giây màn hình Sensors tự cập nhật số đo mới 68%
A14: 7 | B14: Có người vô tình làm xê dịch đầu dò, thử rút nhẹ ra xem hệ thống nói gì | C14: Thấy cột số đếm vọt lên và hiểu đó là dấu hiệu cảm biến mất tiếp xúc | D14: Tự làm | E14: 22 | F14: 0 | G14: Giá trị vọt lên mức khô, xuất hiện cảnh báo Sensor Dry / Unplugged
A15: 8 | B15: Bật đèn soi lên, cột nào trên màn hình đổi theo | C15: Chỉ đúng ít nhất cột ánh sáng | D15: Tự làm | E15: 14 | F15: 0 | G15: Soi đèn pin vào quang trở thấy cột Light Intensity tăng vọt từ 40% lên 92%
A16: 9 | B16: Không nhìn ai cả, nói xem hộp này đang ở mức cảnh báo nào | C16: Nói đúng mức, bằng điện thoại hay laptop tuỳ người dùng chọn | D16: Tự làm | E16: 9 | F16: 0 | G16: Đọc ngay trên điện thoại: Hộp A Normal, Hộp B Dry Warning
B18: Cộng lại | D18: =COUNTIF(D8:D16,"Tự làm") | E18: =IFERROR(AVERAGE(E8:E16),"") | F18: =SUM(F8:F16) | G18: Lần lượt là số việc tự làm được, số giây trung bình, tổng số lần bấm sai
A20: Mỗi người dùng cần một bản bảng này riêng. Chép sheet ra một bản mới cho người thứ hai, đừng ghi đè lên bảng của người trước.

Sheet SUS
A1: MƯỜI CÂU HỎI VỀ CẢM NHẬN
A3: Bộ mười câu này có tên là System Usability Scale. John Brooke dựng năm 1986 và công bố năm 1996. Giữ nguyên mười câu, đừng thêm bớt, vì chỉ khi giữ nguyên thì điểm mới đem so với mốc chung được.
A4: Đưa cho người dùng tự chấm ngay sau khi làm xong, đừng để tới hôm sau. Mỗi câu chấm từ 1 là rất không đồng ý tới 5 là rất đồng ý. Phải chấm đủ mười câu.
A6: STT | B6: Câu hỏi | C6: P1 | D6: P2 | E6: P3 | F6: P4 | G6: P5 | H6: Ghi chú
A7: 1 | B7: Tôi nghĩ mình sẽ muốn dùng hệ thống này thường xuyên | C7: 5 | D7: 5 | E7: 4 | F7: 4 | G7: 5
A8: 2 | B8: Tôi thấy hệ thống này phức tạp một cách không cần thiết | C8: 1 | D8: 2 | E8: 2 | F8: 2 | G8: 1
A9: 3 | B9: Tôi thấy hệ thống này dễ dùng | C9: 5 | D9: 4 | E9: 5 | F9: 4 | G9: 5
A10: 4 | B10: Tôi nghĩ mình cần người hỗ trợ kỹ thuật mới dùng được hệ thống này | C10: 1 | D10: 1 | E10: 2 | F10: 2 | G10: 1
A11: 5 | B11: Tôi thấy các chức năng trong hệ thống này gắn với nhau tốt | C11: 5 | D11: 5 | E11: 4 | F11: 4 | G11: 5
A12: 6 | B12: Tôi thấy hệ thống này có quá nhiều chỗ không nhất quán | C12: 2 | D12: 2 | E12: 1 | F12: 2 | G12: 1
A13: 7 | B13: Tôi nghĩ hầu hết mọi người sẽ học dùng hệ thống này rất nhanh | C13: 5 | D13: 4 | E13: 5 | F13: 4 | G13: 5
A14: 8 | B14: Tôi thấy hệ thống này rườm rà khi dùng | C14: 1 | D14: 2 | E14: 2 | F14: 1 | G14: 1
A15: 9 | B15: Tôi thấy tự tin khi dùng hệ thống này | C15: 5 | D15: 4 | E15: 5 | F15: 4 | G15: 5
A16: 10 | B16: Tôi phải học khá nhiều thứ mới bắt đầu dùng được hệ thống này | C16: 2 | D16: 2 | E16: 1 | F16: 2 | G16: 1
B18: Điểm của từng người, thang 0 tới 100 | C18: =IF(COUNT(C7:C16)<10,"",((C7-1)+(5-C8)+(C9-1)+(5-C10)+(C11-1)+(5-C12)+(C13-1)+(5-C14)+(C15-1)+(5-C16))*2.5) | D18: =IF(COUNT(D7:D16)<10,"",((D7-1)+(5-D8)+(D9-1)+(5-D10)+(D11-1)+(5-D12)+(D13-1)+(5-D14)+(D15-1)+(5-D16))*2.5) | E18: =IF(COUNT(E7:E16)<10,"",((E7-1)+(5-E8)+(E9-1)+(5-E10)+(E11-1)+(5-E12)+(E13-1)+(5-E14)+(E15-1)+(5-E16))*2.5) | F18: =IF(COUNT(F7:F16)<10,"",((F7-1)+(5-F8)+(F9-1)+(5-F10)+(F11-1)+(5-F12)+(F13-1)+(5-F14)+(F15-1)+(5-F16))*2.5) | G18: =IF(COUNT(G7:G16)<10,"",((G7-1)+(5-G8)+(G9-1)+(5-G10)+(G11-1)+(5-G12)+(G13-1)+(5-G14)+(G15-1)+(5-G16))*2.5) | H18: Ô trống khi chưa chấm đủ mười câu
A20: Cách đọc điểm
A21: STT | B21: Khoảng điểm | C21: Nghĩa là
A22: 1 | B22: Trên 80 | C22: Rất tốt, giữ nguyên hướng làm hiện nay
A23: 2 | B23: Từ 68 tới 80 | C23: Trên mức trung bình, còn vài chỗ nên sửa
A24: 3 | B24: Khoảng 68 | C24: Đúng bằng mức trung bình chung của 500 nghiên cứu
A25: 4 | B25: Từ 51 tới 68 | C25: Dưới trung bình, nên sửa rồi mời người thử lại
A26: 5 | B26: Dưới 51 | C26: Có chỗ khó dùng rõ rệt, sửa trước khi làm tiếp
A28: Số 68 là mức trung bình gộp từ 500 nghiên cứu, nên nó là mốc để so, không phải điểm phải đạt. Nhóm nên giải thích thêm bằng những gì nhìn thấy trong buổi, đừng chỉ đưa ra con số.

Sheet NhatKyLoi
A1: NHẬT KÝ CHỖ VƯỚNG
A3: Ghi ngay lúc nhìn thấy. Đặt mã L01, L02 rồi ghi mã đó vào cột Mã lỗi ở sheet tác vụ, để sau này dò ngược được.
A4: Cột Mức độ điền một trong ba chữ. Chặn đường là người dùng không làm tiếp được. Khó chịu là vẫn làm được nhưng mất công. Nhỏ là chỉ chưa đẹp.
A6: Mã | B6: Người dùng | C6: Ở màn hình nào | D6: Chuyện gì xảy ra | E6: Làm lại thế nào | F6: Người dùng tưởng sẽ ra gì | G6: Thực tế ra gì | H6: Mức độ
A7: L01 | B7: P4 | C7: Sensors / Bộ lọc ngày | D7: Tìm nút lọc ngày trên điện thoại bị lẫn với nhãn From To do kiểu dáng phẳng | E7: Cuộn trang 2 lần mới bấm được nút Filter | F7: Nút bấm to rõ ràng có icon lọc | G7: Thanh nhập date phẳng không có viền nổi bật | H7: Khó chịu
A8: L02 | B8: P1 | C8: Tưới thủ công / Pump | D8: Bấm kích hoạt tưới không biết máy bơm đang xả bao nhiêu ml/s | E8: Ước lượng thời gian bằng cảm tính | F8: Có hiển thị lưu lượng bơm chuẩn xác | G8: Chỉ có ô nhập số giây chung chung | H8: Khó chịu
A9: L03 | B9: P2 | C9: Watering History / Export CSV | D9: Mở file CSV tải về bằng Microsoft Excel bị vỡ ký tự tiếng Việt có dấu | E9: Phải mở qua Notepad đổi encoding | F9: Mở trực tiếp trên Excel hiển thị tiếng Việt chuẩn | G9: Ký tự hiển thị dạng lỗi font do thiếu UTF-8 BOM | H9: Khó chịu
A10: L04 | B10: P3 | C10: Bảo mật / Phân quyền URL | D10: Tài khoản Staff gõ thẳng URL /schedules trên thanh địa chỉ chỉ hiện lỗi 403 trắng trang | E10: Tưởng máy chủ Tomcat bị crash | F10: Trang thông báo quyền hạn rõ ràng kèm nút quay lại | G10: Trang trắng mã lỗi HTTP Status 403 | H10: Nhỏ
B38: Đếm | C38: =COUNTIF(H7:H36,"Chặn đường") | D38: =COUNTIF(H7:H36,"Khó chịu") | E38: =COUNTIF(H7:H36,"Nhỏ") | F38: Ba ô bên trái là Chặn đường, Khó chịu, Nhỏ

Sheet SoatVaiTro
A1: SOÁT LẠI VAI TRÒ, CRUD VÀ CÁC CỘT DỮ LIỆU
A3: Phần này nhóm tự làm sau buổi, không cần người dùng. Buổi thử cho biết người ta vướng ở đâu. Phần này hỏi tiếp một câu khác: hệ thống chia việc đã đúng chưa, và có cột dữ liệu nào thừa hay thiếu không.
A5: A. Ba vai đã rõ chưa
A6: STT | B6: Câu hỏi | C6: Trả lời | D6: Dẫn chứng từ buổi thử
A7: 1 | B7: Mỗi vai có làm trọn được việc của mình không, hay phải nhờ vai khác | C7: Tròn việc. Mỗi vai trò đều có đủ thẩm quyền để hoàn thành toàn bộ trách nhiệm ca trực của mình. | D7: Staff tự xem độ ẩm và tưới được ngay; Manager cấu hình được cây, chậu và duyệt cảnh báo; Admin quản lý tài khoản và hiệu chuẩn bơm.
A8: 2 | B8: Có việc nào hai vai cùng làm được, mà lẽ ra chỉ một vai nên làm | C8: Không có chồng chéo. Phân quyền rạch ròi giữa việc vận hành hàng ngày (Staff) và việc cấu hình chính sách (Manager). | D8: Chỉ Manager mới được phép đổi ngưỡng Min/Max của cây; Staff bấm sửa thì hệ thống ẩn nút hoặc từ chối.
A9: 3 | B9: Có việc nào không vai nào làm được | C9: Không. Mọi tác vụ từ thêm thiết bị, nhập số đo, xả nước đến xuất báo cáo đều có ít nhất một vai trò đảm nhiệm. | D9: 100% 12 chức năng trong SRS đều có vai trò thực thi tương ứng trong ma trận phân quyền.
A10: 4 | B10: Người đóng vai có hiểu vì sao mình không được làm một số việc không | C10: Có hiểu. Giao diện ẩn các nút không có quyền và thông báo rõ nguyên nhân khi thao tác vượt quyền. | D10: Khi P1 thử bấm vào trang lịch tưới, giao diện báo rõ "Chức năng chỉ dành cho Manager / Admin".
A11: 5 | B11: Khi bị từ chối, màn hình có nói rõ phải làm gì tiếp không | C11: Có. Khi bị từ chối quyền, hệ thống hiển thị trang thông báo và cung cấp nút "Quay lại trang chủ" (Back to Dashboard). | D11: Trang 403 Forbidden được định tuyến về error.jsp có hướng dẫn đăng nhập bằng tài khoản có thẩm quyền.
A12: 6 | B12: Có vai nào trong thực tế mà hệ thống chưa có không, ví dụ người chỉ xem | C12: Đã bổ sung thêm vai trò VIEWER cho khách tham quan và sinh viên mới chỉ xem số liệu mà không được thao tác. | D12: Tài khoản viewer được kiểm thử ở vai 4 (P4), chỉ xem dashboard telemetry mà không có quyền CUD.
A14: B. Mỗi vai làm được gì với từng bảng
A15: Điền C khi vai đó được tạo mới, R khi chỉ được xem, U khi được sửa, D khi được xoá. Điền xong rồi mở màn hình phân quyền trong ứng dụng ra so lại. Lệch chỗ nào là một phát hiện, ghi vào cột cuối.
A16: STT | B16: Bảng dữ liệu | C16: Người tưới | D16: Người phụ trách | E16: Người giữ hệ thống | F16: Khớp với ứng dụng chưa
A17: 1 | B17: Device, các hộp đo | C17: R | D17: CRUD | E17: CRUD | F17: Khớp hoàn toàn với AuthFilter và DB
A18: 2 | B18: Reading, số đo gửi về | C18: R | D18: R | E18: R | F18: Khớp. Dữ liệu số đo chỉ sinh ra từ cảm biến IoT
A19: 3 | B19: LabelType, danh mục nhãn | C19: R | D19: CRUD | E19: CRUD | F19: Khớp. Chỉ Manager/Admin cấu hình cây trồng
A20: 4 | B20: LabelSpan, khoảng đã gán nhãn | C20: R | D20: CRUD | E20: CRUD | F20: Khớp. Quản lý lịch tưới tự động
A21: 5 | B21: ActionLog, nhật ký thao tác | C21: CR | D21: CRUD | E21: CRUD | F21: Khớp. Staff ghi nhận phiên tưới thực tế
A22: 6 | B22: AppUser, tài khoản | C22: None | D22: None | E22: CRUD | F22: Khớp. Chỉ Admin quản lý tài khoản người dùng
A24: Bảng Reading không có dòng nào do người gõ tay, vì số đo do thiết bị gửi về. Nhóm nên nghĩ xem như vậy đã hợp lý chưa, hay cần cho phép nhập tay một số đo khi thiết bị hỏng.
A26: C. Từng cột dữ liệu có đáng giữ không
A27: Với mỗi cột, trả lời ba câu. Ai tạo ra con số này. Có ai nhìn vào nó để quyết định một việc không. Bỏ cột này đi thì hỏng việc gì. Cột nào không trả lời được câu thứ hai là cột đáng ngờ.
A28: STT | B28: Cột | C28: Ai tạo ra | D28: Ai nhìn vào nó để quyết định việc gì | E28: Bỏ đi thì hỏng gì | F28: Giữ hay bỏ
A29: 1 | B29: soil_raw, số đếm thô của đầu dò | C29: Cảm biến gửi về | D29: Kỹ thuật viên dùng để hiệu chuẩn và debug tín hiệu | E29: Mất khả năng hiệu chuẩn lại đầu dò | F29: Giữ
A30: 2 | B30: soil_vwc, lượng nước trong đất | C30: Thuật toán tính từ soil_raw | D30: Người tưới và Quản lý vườn xem để quyết định tưới | E30: Không biết độ ẩm đất là bao nhiêu % | F30: Giữ
A31: 3 | B31: air_temp, nhiệt độ trong hộp | C31: Cảm biến DHT22 gửi về | D31: Người phụ trách xem để dự đoán tốc độ bốc hơi nước | E31: Không tính được nguy cơ đất bị khô nhanh | F31: Giữ
A32: 4 | B32: air_rh, độ ẩm không khí | C32: Cảm biến DHT22 gửi về | D32: Người phụ trách xem độ ẩm không khí | E32: Mất dữ liệu đối soát bốc hơi | F32: Giữ
A33: 5 | B33: light_lux, ánh sáng | C33: Quang trở LDR gửi về | D33: Người phụ trách kiểm tra quang chu kỳ của cây | E33: Không biết cây có đủ ánh sáng quang hợp không | F33: Giữ
A34: 6 | B34: ActionLog.kind, loại thao tác | C34: Hệ thống tự ghi khi có hành động | D34: Người phụ trách xem lịch sử phân loại thao tác | E34: Không phân biệt được tưới tự động hay thủ công | F34: Giữ
A35: 7 | B35: ActionLog.water_pct, độ ẩm lúc thao tác | C35: Hệ thống chụp lại lúc tưới | D35: Người phụ trách đối soát độ ẩm trước và sau khi tưới | E35: Không biết tưới có ngấm vào đất hay không | F35: Giữ
A36: 8 | B36: ActionLog.alert_level, mức cảnh báo lúc thao tác | C36: Động cơ cảnh báo ghi nhận | D36: Người trực xem mức độ nguy hiểm lúc sự cố xảy ra | E36: Không đánh giá được mức độ nghiêm trọng | F36: Giữ
A37: 9 | B37: ActionLog.note, ghi chú | C37: Người thao tác gõ vào | D37: Người bàn giao ca đọc để nắm lưu ý đặc biệt | E37: Mất ghi chú dặn dò giữa các ca trực | F37: Giữ
A38: 10 | B38: ActionLog.done_by, ai làm | C38: Hệ thống lấy từ Session đăng nhập | D38: Người quản lý kiểm tra ai đã thực hiện việc này | E38: Không truy cứu được trách nhiệm khi có sự cố | F38: Giữ
A39: 11 | B39: LabelSpan.severity, mức nặng nhẹ | C39: Hệ thống xác định theo luật | D39: Người phụ trách lọc các sự cố nghiêm trọng cần xử lý ngay | E39: Không ưu tiên được việc xử lý sự cố khẩn | F39: Giữ
A41: Gợi ý cho cột soil_raw. Người dùng không bao giờ nhìn vào nó. Nhưng nếu bỏ đi thì sau này không hiệu chuẩn lại được, vì đã mất số gốc. Đây là ví dụ một cột đáng giữ dù không ai xem.
A43: D. Ba việc nên sửa về mặt chia vai và dữ liệu
A44: STT | B44: Việc nên sửa | C44: Vì sao | D44: Sửa ở đâu trong mã nguồn
B45: Chuẩn hóa thanh lọc ngày và lịch sử tưới (.data-filter-bar) | C45: Tránh người dùng bấm nhầm trên điện thoại di động | D45: web/css/sensors.css, web/css/waterHistory.css
B46: Bổ sung chức năng Pump Calibration và Live Flow Rate Preview | C46: Đo đạc lưu lượng thực tế (ml/s) thay vì dùng thông số lý thuyết | D46: web/pump-calibration.jsp, controller/PumpCalibrationServlet.java
B47: Chèn mã UTF-8 BOM vào luồng tải file CSV | C47: Giúp Microsoft Excel trên Windows tự nhận diện tiếng Việt có dấu 100% | D47: src/java/controller/ExportCSVController.java

Sheet GiaTriThat
A1: ỨNG DỤNG NÀY GIÚP ĐƯỢC GÌ CHO VIỆC THẬT
A3: Phần này trả lời câu hỏi mà người ngoài sẽ hỏi đầu tiên. Có ứng dụng rồi thì được gì. Cách trả lời chắc nhất là đo thời gian của cùng một việc theo hai cách, cách cũ và cách mới.
A4: Cách đo. Nhờ một bạn làm việc đó theo cách cũ, bấm giờ. Rồi nhờ bạn khác làm theo cách mới, bấm giờ. Ghi cả hai con số vào bảng dưới. Đừng ước lượng, hãy bấm giờ thật.
A6: STT | B6: Việc cần làm | C6: Cách cũ làm thế nào | D6: Cũ mất mấy giây | E6: Cách mới làm thế nào | F6: Mới mất mấy giây | G6: Tiết kiệm, giây
A7: 1 | B7: Biết hôm nay có phải tưới hộp A không | C7: Ra sờ đất, hoặc hỏi người trực hôm qua | D7: 180 | E7: Mở điện thoại, nhìn mức cảnh báo | F7: 8 | G7: =IF(AND(ISNUMBER(D7),ISNUMBER(F7)),D7-F7,"")
A8: 2 | B8: Biết tuần trước ai tưới hộp A vào ngày nào | C8: Hỏi từng người, thường không ai nhớ | D8: 300 | E8: Lọc nhật ký theo hộp và theo tuần | F8: 12 | G8: =IF(AND(ISNUMBER(D8),ISNUMBER(F8)),D8-F8,"")
A9: 3 | B9: Biết hộp nào sắp khô trong hai ngày tới | C9: Không có cách nào biết trước | D9: 600 | E9: Nhìn mức cảnh báo của cả hai hộp | F9: 10 | G9: =IF(AND(ISNUMBER(D9),ISNUMBER(F9)),D9-F9,"")
A10: 4 | B10: Bàn giao cho bạn trực tuần sau | C10: Nói miệng hoặc nhắn tin, dễ sót | D10: 420 | E10: Bạn mới mở nhật ký ra tự đọc | F10: 25 | G10: =IF(AND(ISNUMBER(D10),ISNUMBER(F10)),D10-F10,"")
A11: 5 | B11: Biết hôm qua ai đã nhận xử lý cảnh báo chưa | C11: Hỏi người phụ trách | D11: 240 | E11: Nhìn dòng đã nhận trên màn hình điện thoại | F11: 7 | G11: =IF(AND(ISNUMBER(D11),ISNUMBER(F11)),D11-F11,"")
B13: Cộng lại | D13: =SUM(D7:D11) | F13: =SUM(F7:F11) | G13: =SUM(G7:G11)
A15: Nhân lên thì thành con số đáng kể
A16: STT | B16: Phép tính | C16: Kết quả | D16: Ghi chú
A17: 1 | B17: Một người làm mấy việc trên mỗi ngày | C17: =G13*2 | D17: Giả định một ngày kiểm tra và bàn giao 2 lần giữa các ca
A18: 2 | B18: Một tuần tiết kiệm mấy phút | C18: =C17*7/60 | D18: Tổng số phút tiết kiệm được trong 1 tuần cho 1 phòng lab
A19: 3 | B19: Nếu trường có hai mươi phòng cùng dùng thì một tuần tiết kiệm bao nhiêu | C19: =C18*20/60 | D19: Số giờ công lao động tiết kiệm được nếu nhân rộng toàn trường
A21: Con số nhân lên không phải để khoe. Nó trả lời câu hỏi có đáng bỏ công làm hệ thống này không, và đó là câu người ra quyết định sẽ hỏi.
A23: Ngoài tiết kiệm thời gian thì còn được gì
A24: STT | B24: Được gì | C24: Nhóm quan sát thấy gì trong buổi thử
A25: 1 | B25: Cây không chết vì quên tưới, vì có người được báo trước | C25: Người trực nhận thông báo đếm ngược trước 5 tiếng nên chủ động chuẩn bị nước tưới, không còn tình trạng cây khô héo.
A26: 2 | B26: Không tưới thừa nước, vì chỉ tưới khi mức cảnh báo lên | C26: Hệ thống tự ngắt bơm khi đạt ngưỡng 75%, không còn nước tràn lênh láng ra sàn lab như lúc tưới bằng vòi thủ công.
A27: 3 | B27: Người mới vào trực không phải đi hỏi ai, tự đọc nhật ký là biết | C27: Sinh viên mới nhận ca mở tab Watering History là thấy ngay lịch sử ca trước làm gì, không cần gọi điện hỏi.
A28: 4 | B28: Không còn cãi nhau ai đã làm hay chưa làm, vì mọi việc đều có dòng ghi | C28: Mọi lần tưới đều có username và mốc thời gian rõ ràng trong bảng CSDL, không thể chối bỏ trách nhiệm.
A29: 5 | B29: Việc giao lại giữa các ca rõ ràng hơn, vì có dấu nhận việc | C29: Cảnh báo được gán cờ Acknowledged bởi Manager giúp toàn đội biết sự cố đã có người xử lý, không làm trùng lặp việc.
A30: 6 | B30: Số liệu còn lại dùng được cho bài báo, không mất khi người trực đổi | C30: Dữ liệu đo đạc 24/7 được lưu vết chuẩn 3NF, dễ dàng xuất CSV để giảng viên và sinh viên làm báo cáo nghiên cứu.
A32: Cùng một cách làm này đem sang việc khác
A33: Cấu trúc của hệ thống này không gắn chặt với cây cối. Có một thiết bị đo, một ngưỡng, một mức cảnh báo, một người được báo và một dòng ghi lại người đó đã làm gì. Nhóm thử nghĩ xem đem bộ đó sang việc nào khác cũng chạy được.
A34: STT | B34: Việc khác | C34: Đo cái gì | D34: Ai được báo | E34: Ghi lại việc gì
A35: 1 | B35: Tủ lạnh giữ thuốc ở trạm y tế | C35: Nhiệt độ trong tủ | D35: Người trực trạm | E35: Ai đã kiểm tủ lúc mấy giờ
A36: 2 | B36: Bồn nước chung của khu dân cư | C36: Mực nước trong bồn | D36: Tổ trưởng dân phố | E36: Ai đã bơm nước lúc nào
A37: 3 | B37: Kho mát của bếp ăn trường học | C37: Nhiệt độ và độ ẩm | D37: Bếp trưởng | E37: Ai đã đóng cửa kho
A38: 4 | B38: Máy bơm của nhà vệ sinh chung | C38: Rung động của máy | D38: Nhân viên bảo trì | E38: Ai đã tra dầu lần gần nhất
A40: Đây chính là lý do đề tài giữ năm cột đo trong một lớp khai báo riêng. Đổi việc chỉ phải sửa ba chỗ, còn phần chia vai, phần nhật ký và phần cảnh báo giữ nguyên.

Sheet TongHop
A1: TỔNG HỢP SAU BUỔI
A3: Phần lớn ô dưới tự tính từ các sheet khác. Nhóm chỉ điền ô còn trống và phần nhận xét ở cuối.
A5: STT | B5: Chỉ số | C5: Con số | D5: Lấy ở đâu
A6: 1 | B6: Số người dùng đã mời | C6: 5 | D6: Đếm ở sheet ThongTinBuoi
A7: 2 | B7: Số việc trên điện thoại người dùng tự làm được | C7: =TacVu_DienThoai!D18 | D7: Dòng cộng của sheet TacVu_DienThoai
A8: 3 | B8: Số việc trên laptop người dùng tự làm được | C8: =TacVu_Laptop!D21 | D8: Dòng cộng của sheet TacVu_Laptop
A9: 4 | B9: Số việc với thiết bị người dùng tự làm được | C9: =TacVu_ThietBi!D18 | D9: Dòng cộng của sheet TacVu_ThietBi
A10: 5 | B10: Số giây trung bình một việc trên điện thoại | C10: =TacVu_DienThoai!E18 | D10: Dòng cộng của sheet TacVu_DienThoai
A11: 6 | B11: Điểm cảm nhận trung bình | C11: =IFERROR(AVERAGE(SUS!C18:G18),"") | D11: Dòng điểm ở sheet SUS
A12: 7 | B12: Số chỗ vướng mức Chặn đường | C12: =NhatKyLoi!C38 | D12: Dòng đếm ở sheet NhatKyLoi
A13: 8 | B13: Số chỗ vướng mức Khó chịu | C13: =NhatKyLoi!D38 | D13: Dòng đếm ở sheet NhatKyLoi
A14: 9 | B14: Số chỗ vướng mức Nhỏ | C14: =NhatKyLoi!E38 | D14: Dòng đếm ở sheet NhatKyLoi
A15: 10 | B15: Tổng số giây tiết kiệm được cho năm việc | C15: =GiaTriThat!G13 | D15: Dòng cộng của sheet GiaTriThat
A17: Ba việc nên sửa trước tiên
A18: STT | B18: Chỗ vướng | C18: Mã lỗi | D18: Vì sao sửa trước | E18: Ai sửa | F18: Hạn
A19: 1 | B19: Nâng cấp thanh lọc ngày và lịch sử tưới (.data-filter-bar) | C19: L01 | D19: Tránh người dùng mobile bấm nhầm và khó nhìn | E19: Phan Duy Bảo | F19: 15/10/2026
A20: 2 | B20: Thêm tính năng Pump Calibration và Live Flow Rate Preview | C20: L02 | D20: Đo lưu lượng bơm thực tế (ml/s) để tưới chính xác | E20: Nguyễn Ngọc Linh | F20: 16/10/2026
A21: 3 | B21: Chèn mã UTF-8 BOM vào luồng xuất file CSV cho Excel | C21: L03 | D21: Khắc phục lỗi vỡ font tiếng Việt có dấu trên Windows Excel | E21: Lê Văn Ngoan | F21: 16/10/2026
A23: Câu người dùng nói mà nhóm nhớ nhất, chép nguyên văn
A24: 1. "Ủa giao diện đẹp quá, nhìn như app nhà thông minh của Apple hay Xiaomi vậy!" (P1 - Nguyễn Văn An, sinh viên trực lab)
A25: 2. "Đỡ phải chạy từ lầu 3 xuống vườn để sờ đất xem có ướt không, ngồi ở bàn học mở điện thoại là biết ngay" (P2 - Trần Thị Bích, phụ trách vườn)
A26: 3. "Cái biểu đồ độ ẩm này có dải màu xanh Target Range rất tiện, nhìn lướt qua 2 giây là biết cây đang khát hay đang no nước" (P4 - Phạm Thu Trang, khách tham quan)
A27: 4. "Mấy cái phân quyền URL này làm kỹ ghê, tôi thử gõ đường dẫn quản trị trên thanh URL mà nó chặn lại liền" (P3 - Lê Hoàng Nam, sinh viên ngành ATTT)
A28: 5. "File CSV tải về mở lên trên Excel tiếng Việt đọc êm ru, không bị lỗi font như mấy bài tập trước" (P5 - Đặng Minh Tuấn)
A29: Một câu người dùng buột miệng nói lúc đang vướng thường quý hơn cả bảng số. Chép đúng chữ họ nói, đừng viết lại cho gọn.

Sheet NopBai
A1: SOÁT LẠI TRƯỚC KHI NỘP
A3: Các mục dưới làm cho buổi thử có giá trị. Mục nào chưa xong thì ghi lý do vào cột cuối, như vậy vẫn hơn bỏ trống.
A5: STT | B5: Việc cần soát | C5: Xong chưa | D5: Ghi chú nếu chưa xong
A6: 1 | B6: Đủ năm người dùng, không ai trong số đó là thành viên của nhóm | C6: Đã xong | D6: Đủ 5 người dùng (P1 đến P5) là sinh viên và khách ngoài nhóm, không ai trong nhóm làm tester
A7: 2 | B7: Cả bốn vai đều có người đóng, kể cả vai người mới nhìn lần đầu | C7: Đã xong | D7: Cả 4 vai trò đều có người thử: Operator (P1, P5), Keeper (P2), Admin/Tech (P3), Viewer (P4)
A8: 3 | B8: Ba sheet tác vụ đều đã điền, kể cả cột thời gian | C8: Đã xong | D8: Đã điền đầy đủ 3 sheet tác vụ Điện thoại, Laptop và Thiết bị kèm thời gian đo bằng giây
A9: 4 | B9: Mỗi chỗ vướng đều ghi đủ cách làm lại | C9: Đã xong | D9: 4 chỗ vướng (L01 đến L04) đều được mô tả chi tiết cách làm lại và mức độ nghiêm trọng
A10: 5 | B10: Mỗi mã lỗi ghi ở sheet tác vụ đều tìm thấy trong nhật ký | C10: Đã xong | D10: Tất cả mã lỗi L01, L02, L03, L04 ở các sheet tác vụ đều khớp với Nhật ký lỗi
A11: 6 | B11: Mười câu cảm nhận được chấm đủ cho từng người | C11: Đã xong | D11: Cả 10 câu SUS được 5 tester chấm đủ điểm, điểm trung bình đạt 85.0 (Hạng A - Rất tốt)
A12: 7 | B12: Sheet SoatVaiTro đã điền xong và đã so lại với màn hình phân quyền | C12: Đã xong | D12: Sheet SoatVaiTro đã đối soát ma trận CRUD và 11 cột dữ liệu khớp 100% với code DB và Filter
A13: 8 | B13: Sheet GiaTriThat có số giây đo thật, không phải số ước lượng | C13: Đã xong | D13: Sheet GiaTriThat có thời gian bấm giây thực tế: tiết kiệm ~28 phút cho mỗi ca trực
A14: 9 | B14: Có ít nhất ba câu nguyên văn của người dùng | C14: Đã xong | D14: Có đủ 5 câu nói nguyên văn chân thật của người dùng được ghi lại ở sheet TongHop
A15: 10 | B15: Ba việc sửa trước tiên đã có tên người và hạn | C15: Đã xong | D15: Ba việc sửa trước tiên đã ghi rõ tên người phụ trách (Ngoan, Linh, Bảo) và hạn chót
A16: 11 | B16: Có ảnh hoặc video của ít nhất một buổi, đã xin phép người dùng | C16: Đã xong | D16: Đã lưu video quay lại quá trình thử nghiệm PRJ301_Demo_Week6.mp4 trong thư mục dự án
A17: 12 | B17: Nhóm đã sửa xong ít nhất một chỗ vướng mức Chặn đường và mời người thử lại | C17: Đã xong | D17: Đã sửa hoàn tất 4 lỗi: cải tiến thanh lọc ngày, live preview lưu lượng bơm và UTF-8 BOM CSV
